[06/Sep/2023 08:55:51] WARNING [django.request:224] Unauthorized: /api/dj-rest-auth/user/
[06/Sep/2023 08:55:57] DEBUG [django.template:869] Exception while resolving variable 'name' in template 'unknown'.
Traceback (most recent call last):
  File "/workspace/.pip-modules/lib/python3.8/site-packages/django/core/handlers/exception.py", line 47, in inner
    response = get_response(request)
  File "/workspace/.pip-modules/lib/python3.8/site-packages/django/core/handlers/base.py", line 167, in _get_response
    callback, callback_args, callback_kwargs = self.resolve_request(request)
  File "/workspace/.pip-modules/lib/python3.8/site-packages/django/core/handlers/base.py", line 290, in resolve_request
    resolver_match = resolver.resolve(request.path_info)
  File "/workspace/.pip-modules/lib/python3.8/site-packages/django/urls/resolvers.py", line 589, in resolve
    raise Resolver404({'tried': tried, 'path': new_path})
django.urls.exceptions.Resolver404: {'tried': [[<URLPattern ''>], [<URLResolver <URLPattern list> (admin:admin) 'admin/'>], [<URLResolver <module 'rest_framework.urls' from '/workspace/.pip-modules/lib/python3.8/site-packages/rest_framework/urls.py'> (rest_framework:rest_framework) 'api/api-auth/'>], [<URLPattern 'api/dj-rest-auth/logout'>], [<URLResolver <module 'dj_rest_auth.urls' from '/workspace/.pip-modules/lib/python3.8/site-packages/dj_rest_auth/urls.py'> (None:None) 'api/dj-rest-auth/'>], [<URLResolver <module 'dj_rest_auth.registration.urls' from '/workspace/.pip-modules/lib/python3.8/site-packages/dj_rest_auth/registration/urls.py'> (None:None) 'api/dj-rest-auth/registration/'>], [<URLResolver <module 'profiles.urls' from '/workspace/worth-a-trip-drf/profiles/urls.py'> (None:None) 'api/'>], [<URLResolver <module 'posts.urls' from '/workspace/worth-a-trip-drf/posts/urls.py'> (None:None) 'api/'>], [<URLResolver <module 'likes.urls' from '/workspace/worth-a-trip-drf/likes/urls.py'> (None:None) 'api/'>], [<URLResolver <module 'comments.urls' from '/workspace/worth-a-trip-drf/comments/urls.py'> (None:None) 'api/'>], [<URLResolver <module 'followers.urls' from '/workspace/worth-a-trip-drf/followers/urls.py'> (None:None) 'api/'>], [<URLResolver <module 'wishes.urls' from '/workspace/worth-a-trip-drf/wishes/urls.py'> (None:None) 'api/'>]], 'path': 'posts/3'}

During handling of the above exception, another exception occurred:

Traceback (most recent call last):
  File "/workspace/.pip-modules/lib/python3.8/site-packages/django/template/base.py", line 829, in _resolve_lookup
    current = current[bit]
TypeError: 'URLResolver' object is not subscriptable

During handling of the above exception, another exception occurred:

Traceback (most recent call last):
  File "/workspace/.pip-modules/lib/python3.8/site-packages/django/template/base.py", line 837, in _resolve_lookup
    current = getattr(current, bit)
AttributeError: 'URLResolver' object has no attribute 'name'

During handling of the above exception, another exception occurred:

Traceback (most recent call last):
  File "/workspace/.pip-modules/lib/python3.8/site-packages/django/template/base.py", line 843, in _resolve_lookup
    current = current[int(bit)]
ValueError: invalid literal for int() with base 10: 'name'

During handling of the above exception, another exception occurred:

Traceback (most recent call last):
  File "/workspace/.pip-modules/lib/python3.8/site-packages/django/template/base.py", line 848, in _resolve_lookup
    raise VariableDoesNotExist("Failed lookup for key "
django.template.base.VariableDoesNotExist: Failed lookup for key [name] in <URLResolver <URLPattern list> (admin:admin) 'admin/'>
[06/Sep/2023 08:55:57] DEBUG [django.template:869] Exception while resolving variable 'name' in template 'unknown'.
Traceback (most recent call last):
  File "/workspace/.pip-modules/lib/python3.8/site-packages/django/core/handlers/exception.py", line 47, in inner
    response = get_response(request)
  File "/workspace/.pip-modules/lib/python3.8/site-packages/django/core/handlers/base.py", line 167, in _get_response
    callback, callback_args, callback_kwargs = self.resolve_request(request)
  File "/workspace/.pip-modules/lib/python3.8/site-packages/django/core/handlers/base.py", line 290, in resolve_request
    resolver_match = resolver.resolve(request.path_info)
  File "/workspace/.pip-modules/lib/python3.8/site-packages/django/urls/resolvers.py", line 589, in resolve
    raise Resolver404({'tried': tried, 'path': new_path})
django.urls.exceptions.Resolver404: {'tried': [[<URLPattern ''>], [<URLResolver <URLPattern list> (admin:admin) 'admin/'>], [<URLResolver <module 'rest_framework.urls' from '/workspace/.pip-modules/lib/python3.8/site-packages/rest_framework/urls.py'> (rest_framework:rest_framework) 'api/api-auth/'>], [<URLPattern 'api/dj-rest-auth/logout'>], [<URLResolver <module 'dj_rest_auth.urls' from '/workspace/.pip-modules/lib/python3.8/site-packages/dj_rest_auth/urls.py'> (None:None) 'api/dj-rest-auth/'>], [<URLResolver <module 'dj_rest_auth.registration.urls' from '/workspace/.pip-modules/lib/python3.8/site-packages/dj_rest_auth/registration/urls.py'> (None:None) 'api/dj-rest-auth/registration/'>], [<URLResolver <module 'profiles.urls' from '/workspace/worth-a-trip-drf/profiles/urls.py'> (None:None) 'api/'>], [<URLResolver <module 'posts.urls' from '/workspace/worth-a-trip-drf/posts/urls.py'> (None:None) 'api/'>], [<URLResolver <module 'likes.urls' from '/workspace/worth-a-trip-drf/likes/urls.py'> (None:None) 'api/'>], [<URLResolver <module 'comments.urls' from '/workspace/worth-a-trip-drf/comments/urls.py'> (None:None) 'api/'>], [<URLResolver <module 'followers.urls' from '/workspace/worth-a-trip-drf/followers/urls.py'> (None:None) 'api/'>], [<URLResolver <module 'wishes.urls' from '/workspace/worth-a-trip-drf/wishes/urls.py'> (None:None) 'api/'>]], 'path': 'posts/3'}

During handling of the above exception, another exception occurred:

Traceback (most recent call last):
  File "/workspace/.pip-modules/lib/python3.8/site-packages/django/template/base.py", line 829, in _resolve_lookup
    current = current[bit]
TypeError: 'URLResolver' object is not subscriptable

During handling of the above exception, another exception occurred:

Traceback (most recent call last):
  File "/workspace/.pip-modules/lib/python3.8/site-packages/django/template/base.py", line 837, in _resolve_lookup
    current = getattr(current, bit)
AttributeError: 'URLResolver' object has no attribute 'name'

During handling of the above exception, another exception occurred:

Traceback (most recent call last):
  File "/workspace/.pip-modules/lib/python3.8/site-packages/django/template/base.py", line 843, in _resolve_lookup
    current = current[int(bit)]
ValueError: invalid literal for int() with base 10: 'name'

During handling of the above exception, another exception occurred:

Traceback (most recent call last):
  File "/workspace/.pip-modules/lib/python3.8/site-packages/django/template/base.py", line 848, in _resolve_lookup
    raise VariableDoesNotExist("Failed lookup for key "
django.template.base.VariableDoesNotExist: Failed lookup for key [name] in <URLResolver <module 'rest_framework.urls' from '/workspace/.pip-modules/lib/python3.8/site-packages/rest_framework/urls.py'> (rest_framework:rest_framework) 'api/api-auth/'>
[06/Sep/2023 08:55:57] DEBUG [django.template:869] Exception while resolving variable 'name' in template 'unknown'.
Traceback (most recent call last):
  File "/workspace/.pip-modules/lib/python3.8/site-packages/django/core/handlers/exception.py", line 47, in inner
    response = get_response(request)
  File "/workspace/.pip-modules/lib/python3.8/site-packages/django/core/handlers/base.py", line 167, in _get_response
    callback, callback_args, callback_kwargs = self.resolve_request(request)
  File "/workspace/.pip-modules/lib/python3.8/site-packages/django/core/handlers/base.py", line 290, in resolve_request
    resolver_match = resolver.resolve(request.path_info)
  File "/workspace/.pip-modules/lib/python3.8/site-packages/django/urls/resolvers.py", line 589, in resolve
    raise Resolver404({'tried': tried, 'path': new_path})
django.urls.exceptions.Resolver404: {'tried': [[<URLPattern ''>], [<URLResolver <URLPattern list> (admin:admin) 'admin/'>], [<URLResolver <module 'rest_framework.urls' from '/workspace/.pip-modules/lib/python3.8/site-packages/rest_framework/urls.py'> (rest_framework:rest_framework) 'api/api-auth/'>], [<URLPattern 'api/dj-rest-auth/logout'>], [<URLResolver <module 'dj_rest_auth.urls' from '/workspace/.pip-modules/lib/python3.8/site-packages/dj_rest_auth/urls.py'> (None:None) 'api/dj-rest-auth/'>], [<URLResolver <module 'dj_rest_auth.registration.urls' from '/workspace/.pip-modules/lib/python3.8/site-packages/dj_rest_auth/registration/urls.py'> (None:None) 'api/dj-rest-auth/registration/'>], [<URLResolver <module 'profiles.urls' from '/workspace/worth-a-trip-drf/profiles/urls.py'> (None:None) 'api/'>], [<URLResolver <module 'posts.urls' from '/workspace/worth-a-trip-drf/posts/urls.py'> (None:None) 'api/'>], [<URLResolver <module 'likes.urls' from '/workspace/worth-a-trip-drf/likes/urls.py'> (None:None) 'api/'>], [<URLResolver <module 'comments.urls' from '/workspace/worth-a-trip-drf/comments/urls.py'> (None:None) 'api/'>], [<URLResolver <module 'followers.urls' from '/workspace/worth-a-trip-drf/followers/urls.py'> (None:None) 'api/'>], [<URLResolver <module 'wishes.urls' from '/workspace/worth-a-trip-drf/wishes/urls.py'> (None:None) 'api/'>]], 'path': 'posts/3'}

During handling of the above exception, another exception occurred:

Traceback (most recent call last):
  File "/workspace/.pip-modules/lib/python3.8/site-packages/django/template/base.py", line 829, in _resolve_lookup
    current = current[bit]
TypeError: 'URLResolver' object is not subscriptable

During handling of the above exception, another exception occurred:

Traceback (most recent call last):
  File "/workspace/.pip-modules/lib/python3.8/site-packages/django/template/base.py", line 837, in _resolve_lookup
    current = getattr(current, bit)
AttributeError: 'URLResolver' object has no attribute 'name'

During handling of the above exception, another exception occurred:

Traceback (most recent call last):
  File "/workspace/.pip-modules/lib/python3.8/site-packages/django/template/base.py", line 843, in _resolve_lookup
    current = current[int(bit)]
ValueError: invalid literal for int() with base 10: 'name'

During handling of the above exception, another exception occurred:

Traceback (most recent call last):
  File "/workspace/.pip-modules/lib/python3.8/site-packages/django/template/base.py", line 848, in _resolve_lookup
    raise VariableDoesNotExist("Failed lookup for key "
django.template.base.VariableDoesNotExist: Failed lookup for key [name] in <URLResolver <module 'dj_rest_auth.urls' from '/workspace/.pip-modules/lib/python3.8/site-packages/dj_rest_auth/urls.py'> (None:None) 'api/dj-rest-auth/'>
[06/Sep/2023 08:55:57] DEBUG [django.template:869] Exception while resolving variable 'name' in template 'unknown'.
Traceback (most recent call last):
  File "/workspace/.pip-modules/lib/python3.8/site-packages/django/core/handlers/exception.py", line 47, in inner
    response = get_response(request)
  File "/workspace/.pip-modules/lib/python3.8/site-packages/django/core/handlers/base.py", line 167, in _get_response
    callback, callback_args, callback_kwargs = self.resolve_request(request)
  File "/workspace/.pip-modules/lib/python3.8/site-packages/django/core/handlers/base.py", line 290, in resolve_request
    resolver_match = resolver.resolve(request.path_info)
  File "/workspace/.pip-modules/lib/python3.8/site-packages/django/urls/resolvers.py", line 589, in resolve
    raise Resolver404({'tried': tried, 'path': new_path})
django.urls.exceptions.Resolver404: {'tried': [[<URLPattern ''>], [<URLResolver <URLPattern list> (admin:admin) 'admin/'>], [<URLResolver <module 'rest_framework.urls' from '/workspace/.pip-modules/lib/python3.8/site-packages/rest_framework/urls.py'> (rest_framework:rest_framework) 'api/api-auth/'>], [<URLPattern 'api/dj-rest-auth/logout'>], [<URLResolver <module 'dj_rest_auth.urls' from '/workspace/.pip-modules/lib/python3.8/site-packages/dj_rest_auth/urls.py'> (None:None) 'api/dj-rest-auth/'>], [<URLResolver <module 'dj_rest_auth.registration.urls' from '/workspace/.pip-modules/lib/python3.8/site-packages/dj_rest_auth/registration/urls.py'> (None:None) 'api/dj-rest-auth/registration/'>], [<URLResolver <module 'profiles.urls' from '/workspace/worth-a-trip-drf/profiles/urls.py'> (None:None) 'api/'>], [<URLResolver <module 'posts.urls' from '/workspace/worth-a-trip-drf/posts/urls.py'> (None:None) 'api/'>], [<URLResolver <module 'likes.urls' from '/workspace/worth-a-trip-drf/likes/urls.py'> (None:None) 'api/'>], [<URLResolver <module 'comments.urls' from '/workspace/worth-a-trip-drf/comments/urls.py'> (None:None) 'api/'>], [<URLResolver <module 'followers.urls' from '/workspace/worth-a-trip-drf/followers/urls.py'> (None:None) 'api/'>], [<URLResolver <module 'wishes.urls' from '/workspace/worth-a-trip-drf/wishes/urls.py'> (None:None) 'api/'>]], 'path': 'posts/3'}

During handling of the above exception, another exception occurred:

Traceback (most recent call last):
  File "/workspace/.pip-modules/lib/python3.8/site-packages/django/template/base.py", line 829, in _resolve_lookup
    current = current[bit]
TypeError: 'URLResolver' object is not subscriptable

During handling of the above exception, another exception occurred:

Traceback (most recent call last):
  File "/workspace/.pip-modules/lib/python3.8/site-packages/django/template/base.py", line 837, in _resolve_lookup
    current = getattr(current, bit)
AttributeError: 'URLResolver' object has no attribute 'name'

During handling of the above exception, another exception occurred:

Traceback (most recent call last):
  File "/workspace/.pip-modules/lib/python3.8/site-packages/django/template/base.py", line 843, in _resolve_lookup
    current = current[int(bit)]
ValueError: invalid literal for int() with base 10: 'name'

During handling of the above exception, another exception occurred:

Traceback (most recent call last):
  File "/workspace/.pip-modules/lib/python3.8/site-packages/django/template/base.py", line 848, in _resolve_lookup
    raise VariableDoesNotExist("Failed lookup for key "
django.template.base.VariableDoesNotExist: Failed lookup for key [name] in <URLResolver <module 'dj_rest_auth.registration.urls' from '/workspace/.pip-modules/lib/python3.8/site-packages/dj_rest_auth/registration/urls.py'> (None:None) 'api/dj-rest-auth/registration/'>
[06/Sep/2023 08:55:57] DEBUG [django.template:869] Exception while resolving variable 'name' in template 'unknown'.
Traceback (most recent call last):
  File "/workspace/.pip-modules/lib/python3.8/site-packages/django/core/handlers/exception.py", line 47, in inner
    response = get_response(request)
  File "/workspace/.pip-modules/lib/python3.8/site-packages/django/core/handlers/base.py", line 167, in _get_response
    callback, callback_args, callback_kwargs = self.resolve_request(request)
  File "/workspace/.pip-modules/lib/python3.8/site-packages/django/core/handlers/base.py", line 290, in resolve_request
    resolver_match = resolver.resolve(request.path_info)
  File "/workspace/.pip-modules/lib/python3.8/site-packages/django/urls/resolvers.py", line 589, in resolve
    raise Resolver404({'tried': tried, 'path': new_path})
django.urls.exceptions.Resolver404: {'tried': [[<URLPattern ''>], [<URLResolver <URLPattern list> (admin:admin) 'admin/'>], [<URLResolver <module 'rest_framework.urls' from '/workspace/.pip-modules/lib/python3.8/site-packages/rest_framework/urls.py'> (rest_framework:rest_framework) 'api/api-auth/'>], [<URLPattern 'api/dj-rest-auth/logout'>], [<URLResolver <module 'dj_rest_auth.urls' from '/workspace/.pip-modules/lib/python3.8/site-packages/dj_rest_auth/urls.py'> (None:None) 'api/dj-rest-auth/'>], [<URLResolver <module 'dj_rest_auth.registration.urls' from '/workspace/.pip-modules/lib/python3.8/site-packages/dj_rest_auth/registration/urls.py'> (None:None) 'api/dj-rest-auth/registration/'>], [<URLResolver <module 'profiles.urls' from '/workspace/worth-a-trip-drf/profiles/urls.py'> (None:None) 'api/'>], [<URLResolver <module 'posts.urls' from '/workspace/worth-a-trip-drf/posts/urls.py'> (None:None) 'api/'>], [<URLResolver <module 'likes.urls' from '/workspace/worth-a-trip-drf/likes/urls.py'> (None:None) 'api/'>], [<URLResolver <module 'comments.urls' from '/workspace/worth-a-trip-drf/comments/urls.py'> (None:None) 'api/'>], [<URLResolver <module 'followers.urls' from '/workspace/worth-a-trip-drf/followers/urls.py'> (None:None) 'api/'>], [<URLResolver <module 'wishes.urls' from '/workspace/worth-a-trip-drf/wishes/urls.py'> (None:None) 'api/'>]], 'path': 'posts/3'}

During handling of the above exception, another exception occurred:

Traceback (most recent call last):
  File "/workspace/.pip-modules/lib/python3.8/site-packages/django/template/base.py", line 829, in _resolve_lookup
    current = current[bit]
TypeError: 'URLResolver' object is not subscriptable

During handling of the above exception, another exception occurred:

Traceback (most recent call last):
  File "/workspace/.pip-modules/lib/python3.8/site-packages/django/template/base.py", line 837, in _resolve_lookup
    current = getattr(current, bit)
AttributeError: 'URLResolver' object has no attribute 'name'

During handling of the above exception, another exception occurred:

Traceback (most recent call last):
  File "/workspace/.pip-modules/lib/python3.8/site-packages/django/template/base.py", line 843, in _resolve_lookup
    current = current[int(bit)]
ValueError: invalid literal for int() with base 10: 'name'

During handling of the above exception, another exception occurred:

Traceback (most recent call last):
  File "/workspace/.pip-modules/lib/python3.8/site-packages/django/template/base.py", line 848, in _resolve_lookup
    raise VariableDoesNotExist("Failed lookup for key "
django.template.base.VariableDoesNotExist: Failed lookup for key [name] in <URLResolver <module 'profiles.urls' from '/workspace/worth-a-trip-drf/profiles/urls.py'> (None:None) 'api/'>
[06/Sep/2023 08:55:57] DEBUG [django.template:869] Exception while resolving variable 'name' in template 'unknown'.
Traceback (most recent call last):
  File "/workspace/.pip-modules/lib/python3.8/site-packages/django/core/handlers/exception.py", line 47, in inner
    response = get_response(request)
  File "/workspace/.pip-modules/lib/python3.8/site-packages/django/core/handlers/base.py", line 167, in _get_response
    callback, callback_args, callback_kwargs = self.resolve_request(request)
  File "/workspace/.pip-modules/lib/python3.8/site-packages/django/core/handlers/base.py", line 290, in resolve_request
    resolver_match = resolver.resolve(request.path_info)
  File "/workspace/.pip-modules/lib/python3.8/site-packages/django/urls/resolvers.py", line 589, in resolve
    raise Resolver404({'tried': tried, 'path': new_path})
django.urls.exceptions.Resolver404: {'tried': [[<URLPattern ''>], [<URLResolver <URLPattern list> (admin:admin) 'admin/'>], [<URLResolver <module 'rest_framework.urls' from '/workspace/.pip-modules/lib/python3.8/site-packages/rest_framework/urls.py'> (rest_framework:rest_framework) 'api/api-auth/'>], [<URLPattern 'api/dj-rest-auth/logout'>], [<URLResolver <module 'dj_rest_auth.urls' from '/workspace/.pip-modules/lib/python3.8/site-packages/dj_rest_auth/urls.py'> (None:None) 'api/dj-rest-auth/'>], [<URLResolver <module 'dj_rest_auth.registration.urls' from '/workspace/.pip-modules/lib/python3.8/site-packages/dj_rest_auth/registration/urls.py'> (None:None) 'api/dj-rest-auth/registration/'>], [<URLResolver <module 'profiles.urls' from '/workspace/worth-a-trip-drf/profiles/urls.py'> (None:None) 'api/'>], [<URLResolver <module 'posts.urls' from '/workspace/worth-a-trip-drf/posts/urls.py'> (None:None) 'api/'>], [<URLResolver <module 'likes.urls' from '/workspace/worth-a-trip-drf/likes/urls.py'> (None:None) 'api/'>], [<URLResolver <module 'comments.urls' from '/workspace/worth-a-trip-drf/comments/urls.py'> (None:None) 'api/'>], [<URLResolver <module 'followers.urls' from '/workspace/worth-a-trip-drf/followers/urls.py'> (None:None) 'api/'>], [<URLResolver <module 'wishes.urls' from '/workspace/worth-a-trip-drf/wishes/urls.py'> (None:None) 'api/'>]], 'path': 'posts/3'}

During handling of the above exception, another exception occurred:

Traceback (most recent call last):
  File "/workspace/.pip-modules/lib/python3.8/site-packages/django/template/base.py", line 829, in _resolve_lookup
    current = current[bit]
TypeError: 'URLResolver' object is not subscriptable

During handling of the above exception, another exception occurred:

Traceback (most recent call last):
  File "/workspace/.pip-modules/lib/python3.8/site-packages/django/template/base.py", line 837, in _resolve_lookup
    current = getattr(current, bit)
AttributeError: 'URLResolver' object has no attribute 'name'

During handling of the above exception, another exception occurred:

Traceback (most recent call last):
  File "/workspace/.pip-modules/lib/python3.8/site-packages/django/template/base.py", line 843, in _resolve_lookup
    current = current[int(bit)]
ValueError: invalid literal for int() with base 10: 'name'

During handling of the above exception, another exception occurred:

Traceback (most recent call last):
  File "/workspace/.pip-modules/lib/python3.8/site-packages/django/template/base.py", line 848, in _resolve_lookup
    raise VariableDoesNotExist("Failed lookup for key "
django.template.base.VariableDoesNotExist: Failed lookup for key [name] in <URLResolver <module 'posts.urls' from '/workspace/worth-a-trip-drf/posts/urls.py'> (None:None) 'api/'>
[06/Sep/2023 08:55:57] DEBUG [django.template:869] Exception while resolving variable 'name' in template 'unknown'.
Traceback (most recent call last):
  File "/workspace/.pip-modules/lib/python3.8/site-packages/django/core/handlers/exception.py", line 47, in inner
    response = get_response(request)
  File "/workspace/.pip-modules/lib/python3.8/site-packages/django/core/handlers/base.py", line 167, in _get_response
    callback, callback_args, callback_kwargs = self.resolve_request(request)
  File "/workspace/.pip-modules/lib/python3.8/site-packages/django/core/handlers/base.py", line 290, in resolve_request
    resolver_match = resolver.resolve(request.path_info)
  File "/workspace/.pip-modules/lib/python3.8/site-packages/django/urls/resolvers.py", line 589, in resolve
    raise Resolver404({'tried': tried, 'path': new_path})
django.urls.exceptions.Resolver404: {'tried': [[<URLPattern ''>], [<URLResolver <URLPattern list> (admin:admin) 'admin/'>], [<URLResolver <module 'rest_framework.urls' from '/workspace/.pip-modules/lib/python3.8/site-packages/rest_framework/urls.py'> (rest_framework:rest_framework) 'api/api-auth/'>], [<URLPattern 'api/dj-rest-auth/logout'>], [<URLResolver <module 'dj_rest_auth.urls' from '/workspace/.pip-modules/lib/python3.8/site-packages/dj_rest_auth/urls.py'> (None:None) 'api/dj-rest-auth/'>], [<URLResolver <module 'dj_rest_auth.registration.urls' from '/workspace/.pip-modules/lib/python3.8/site-packages/dj_rest_auth/registration/urls.py'> (None:None) 'api/dj-rest-auth/registration/'>], [<URLResolver <module 'profiles.urls' from '/workspace/worth-a-trip-drf/profiles/urls.py'> (None:None) 'api/'>], [<URLResolver <module 'posts.urls' from '/workspace/worth-a-trip-drf/posts/urls.py'> (None:None) 'api/'>], [<URLResolver <module 'likes.urls' from '/workspace/worth-a-trip-drf/likes/urls.py'> (None:None) 'api/'>], [<URLResolver <module 'comments.urls' from '/workspace/worth-a-trip-drf/comments/urls.py'> (None:None) 'api/'>], [<URLResolver <module 'followers.urls' from '/workspace/worth-a-trip-drf/followers/urls.py'> (None:None) 'api/'>], [<URLResolver <module 'wishes.urls' from '/workspace/worth-a-trip-drf/wishes/urls.py'> (None:None) 'api/'>]], 'path': 'posts/3'}

During handling of the above exception, another exception occurred:

Traceback (most recent call last):
  File "/workspace/.pip-modules/lib/python3.8/site-packages/django/template/base.py", line 829, in _resolve_lookup
    current = current[bit]
TypeError: 'URLResolver' object is not subscriptable

During handling of the above exception, another exception occurred:

Traceback (most recent call last):
  File "/workspace/.pip-modules/lib/python3.8/site-packages/django/template/base.py", line 837, in _resolve_lookup
    current = getattr(current, bit)
AttributeError: 'URLResolver' object has no attribute 'name'

During handling of the above exception, another exception occurred:

Traceback (most recent call last):
  File "/workspace/.pip-modules/lib/python3.8/site-packages/django/template/base.py", line 843, in _resolve_lookup
    current = current[int(bit)]
ValueError: invalid literal for int() with base 10: 'name'

During handling of the above exception, another exception occurred:

Traceback (most recent call last):
  File "/workspace/.pip-modules/lib/python3.8/site-packages/django/template/base.py", line 848, in _resolve_lookup
    raise VariableDoesNotExist("Failed lookup for key "
django.template.base.VariableDoesNotExist: Failed lookup for key [name] in <URLResolver <module 'likes.urls' from '/workspace/worth-a-trip-drf/likes/urls.py'> (None:None) 'api/'>
[06/Sep/2023 08:55:57] DEBUG [django.template:869] Exception while resolving variable 'name' in template 'unknown'.
Traceback (most recent call last):
  File "/workspace/.pip-modules/lib/python3.8/site-packages/django/core/handlers/exception.py", line 47, in inner
    response = get_response(request)
  File "/workspace/.pip-modules/lib/python3.8/site-packages/django/core/handlers/base.py", line 167, in _get_response
    callback, callback_args, callback_kwargs = self.resolve_request(request)
  File "/workspace/.pip-modules/lib/python3.8/site-packages/django/core/handlers/base.py", line 290, in resolve_request
    resolver_match = resolver.resolve(request.path_info)
  File "/workspace/.pip-modules/lib/python3.8/site-packages/django/urls/resolvers.py", line 589, in resolve
    raise Resolver404({'tried': tried, 'path': new_path})
django.urls.exceptions.Resolver404: {'tried': [[<URLPattern ''>], [<URLResolver <URLPattern list> (admin:admin) 'admin/'>], [<URLResolver <module 'rest_framework.urls' from '/workspace/.pip-modules/lib/python3.8/site-packages/rest_framework/urls.py'> (rest_framework:rest_framework) 'api/api-auth/'>], [<URLPattern 'api/dj-rest-auth/logout'>], [<URLResolver <module 'dj_rest_auth.urls' from '/workspace/.pip-modules/lib/python3.8/site-packages/dj_rest_auth/urls.py'> (None:None) 'api/dj-rest-auth/'>], [<URLResolver <module 'dj_rest_auth.registration.urls' from '/workspace/.pip-modules/lib/python3.8/site-packages/dj_rest_auth/registration/urls.py'> (None:None) 'api/dj-rest-auth/registration/'>], [<URLResolver <module 'profiles.urls' from '/workspace/worth-a-trip-drf/profiles/urls.py'> (None:None) 'api/'>], [<URLResolver <module 'posts.urls' from '/workspace/worth-a-trip-drf/posts/urls.py'> (None:None) 'api/'>], [<URLResolver <module 'likes.urls' from '/workspace/worth-a-trip-drf/likes/urls.py'> (None:None) 'api/'>], [<URLResolver <module 'comments.urls' from '/workspace/worth-a-trip-drf/comments/urls.py'> (None:None) 'api/'>], [<URLResolver <module 'followers.urls' from '/workspace/worth-a-trip-drf/followers/urls.py'> (None:None) 'api/'>], [<URLResolver <module 'wishes.urls' from '/workspace/worth-a-trip-drf/wishes/urls.py'> (None:None) 'api/'>]], 'path': 'posts/3'}

During handling of the above exception, another exception occurred:

Traceback (most recent call last):
  File "/workspace/.pip-modules/lib/python3.8/site-packages/django/template/base.py", line 829, in _resolve_lookup
    current = current[bit]
TypeError: 'URLResolver' object is not subscriptable

During handling of the above exception, another exception occurred:

Traceback (most recent call last):
  File "/workspace/.pip-modules/lib/python3.8/site-packages/django/template/base.py", line 837, in _resolve_lookup
    current = getattr(current, bit)
AttributeError: 'URLResolver' object has no attribute 'name'

During handling of the above exception, another exception occurred:

Traceback (most recent call last):
  File "/workspace/.pip-modules/lib/python3.8/site-packages/django/template/base.py", line 843, in _resolve_lookup
    current = current[int(bit)]
ValueError: invalid literal for int() with base 10: 'name'

During handling of the above exception, another exception occurred:

Traceback (most recent call last):
  File "/workspace/.pip-modules/lib/python3.8/site-packages/django/template/base.py", line 848, in _resolve_lookup
    raise VariableDoesNotExist("Failed lookup for key "
django.template.base.VariableDoesNotExist: Failed lookup for key [name] in <URLResolver <module 'comments.urls' from '/workspace/worth-a-trip-drf/comments/urls.py'> (None:None) 'api/'>
[06/Sep/2023 08:55:57] DEBUG [django.template:869] Exception while resolving variable 'name' in template 'unknown'.
Traceback (most recent call last):
  File "/workspace/.pip-modules/lib/python3.8/site-packages/django/core/handlers/exception.py", line 47, in inner
    response = get_response(request)
  File "/workspace/.pip-modules/lib/python3.8/site-packages/django/core/handlers/base.py", line 167, in _get_response
    callback, callback_args, callback_kwargs = self.resolve_request(request)
  File "/workspace/.pip-modules/lib/python3.8/site-packages/django/core/handlers/base.py", line 290, in resolve_request
    resolver_match = resolver.resolve(request.path_info)
  File "/workspace/.pip-modules/lib/python3.8/site-packages/django/urls/resolvers.py", line 589, in resolve
    raise Resolver404({'tried': tried, 'path': new_path})
django.urls.exceptions.Resolver404: {'tried': [[<URLPattern ''>], [<URLResolver <URLPattern list> (admin:admin) 'admin/'>], [<URLResolver <module 'rest_framework.urls' from '/workspace/.pip-modules/lib/python3.8/site-packages/rest_framework/urls.py'> (rest_framework:rest_framework) 'api/api-auth/'>], [<URLPattern 'api/dj-rest-auth/logout'>], [<URLResolver <module 'dj_rest_auth.urls' from '/workspace/.pip-modules/lib/python3.8/site-packages/dj_rest_auth/urls.py'> (None:None) 'api/dj-rest-auth/'>], [<URLResolver <module 'dj_rest_auth.registration.urls' from '/workspace/.pip-modules/lib/python3.8/site-packages/dj_rest_auth/registration/urls.py'> (None:None) 'api/dj-rest-auth/registration/'>], [<URLResolver <module 'profiles.urls' from '/workspace/worth-a-trip-drf/profiles/urls.py'> (None:None) 'api/'>], [<URLResolver <module 'posts.urls' from '/workspace/worth-a-trip-drf/posts/urls.py'> (None:None) 'api/'>], [<URLResolver <module 'likes.urls' from '/workspace/worth-a-trip-drf/likes/urls.py'> (None:None) 'api/'>], [<URLResolver <module 'comments.urls' from '/workspace/worth-a-trip-drf/comments/urls.py'> (None:None) 'api/'>], [<URLResolver <module 'followers.urls' from '/workspace/worth-a-trip-drf/followers/urls.py'> (None:None) 'api/'>], [<URLResolver <module 'wishes.urls' from '/workspace/worth-a-trip-drf/wishes/urls.py'> (None:None) 'api/'>]], 'path': 'posts/3'}

During handling of the above exception, another exception occurred:

Traceback (most recent call last):
  File "/workspace/.pip-modules/lib/python3.8/site-packages/django/template/base.py", line 829, in _resolve_lookup
    current = current[bit]
TypeError: 'URLResolver' object is not subscriptable

During handling of the above exception, another exception occurred:

Traceback (most recent call last):
  File "/workspace/.pip-modules/lib/python3.8/site-packages/django/template/base.py", line 837, in _resolve_lookup
    current = getattr(current, bit)
AttributeError: 'URLResolver' object has no attribute 'name'

During handling of the above exception, another exception occurred:

Traceback (most recent call last):
  File "/workspace/.pip-modules/lib/python3.8/site-packages/django/template/base.py", line 843, in _resolve_lookup
    current = current[int(bit)]
ValueError: invalid literal for int() with base 10: 'name'

During handling of the above exception, another exception occurred:

Traceback (most recent call last):
  File "/workspace/.pip-modules/lib/python3.8/site-packages/django/template/base.py", line 848, in _resolve_lookup
    raise VariableDoesNotExist("Failed lookup for key "
django.template.base.VariableDoesNotExist: Failed lookup for key [name] in <URLResolver <module 'followers.urls' from '/workspace/worth-a-trip-drf/followers/urls.py'> (None:None) 'api/'>
[06/Sep/2023 08:55:57] DEBUG [django.template:869] Exception while resolving variable 'name' in template 'unknown'.
Traceback (most recent call last):
  File "/workspace/.pip-modules/lib/python3.8/site-packages/django/core/handlers/exception.py", line 47, in inner
    response = get_response(request)
  File "/workspace/.pip-modules/lib/python3.8/site-packages/django/core/handlers/base.py", line 167, in _get_response
    callback, callback_args, callback_kwargs = self.resolve_request(request)
  File "/workspace/.pip-modules/lib/python3.8/site-packages/django/core/handlers/base.py", line 290, in resolve_request
    resolver_match = resolver.resolve(request.path_info)
  File "/workspace/.pip-modules/lib/python3.8/site-packages/django/urls/resolvers.py", line 589, in resolve
    raise Resolver404({'tried': tried, 'path': new_path})
django.urls.exceptions.Resolver404: {'tried': [[<URLPattern ''>], [<URLResolver <URLPattern list> (admin:admin) 'admin/'>], [<URLResolver <module 'rest_framework.urls' from '/workspace/.pip-modules/lib/python3.8/site-packages/rest_framework/urls.py'> (rest_framework:rest_framework) 'api/api-auth/'>], [<URLPattern 'api/dj-rest-auth/logout'>], [<URLResolver <module 'dj_rest_auth.urls' from '/workspace/.pip-modules/lib/python3.8/site-packages/dj_rest_auth/urls.py'> (None:None) 'api/dj-rest-auth/'>], [<URLResolver <module 'dj_rest_auth.registration.urls' from '/workspace/.pip-modules/lib/python3.8/site-packages/dj_rest_auth/registration/urls.py'> (None:None) 'api/dj-rest-auth/registration/'>], [<URLResolver <module 'profiles.urls' from '/workspace/worth-a-trip-drf/profiles/urls.py'> (None:None) 'api/'>], [<URLResolver <module 'posts.urls' from '/workspace/worth-a-trip-drf/posts/urls.py'> (None:None) 'api/'>], [<URLResolver <module 'likes.urls' from '/workspace/worth-a-trip-drf/likes/urls.py'> (None:None) 'api/'>], [<URLResolver <module 'comments.urls' from '/workspace/worth-a-trip-drf/comments/urls.py'> (None:None) 'api/'>], [<URLResolver <module 'followers.urls' from '/workspace/worth-a-trip-drf/followers/urls.py'> (None:None) 'api/'>], [<URLResolver <module 'wishes.urls' from '/workspace/worth-a-trip-drf/wishes/urls.py'> (None:None) 'api/'>]], 'path': 'posts/3'}

During handling of the above exception, another exception occurred:

Traceback (most recent call last):
  File "/workspace/.pip-modules/lib/python3.8/site-packages/django/template/base.py", line 829, in _resolve_lookup
    current = current[bit]
TypeError: 'URLResolver' object is not subscriptable

During handling of the above exception, another exception occurred:

Traceback (most recent call last):
  File "/workspace/.pip-modules/lib/python3.8/site-packages/django/template/base.py", line 837, in _resolve_lookup
    current = getattr(current, bit)
AttributeError: 'URLResolver' object has no attribute 'name'

During handling of the above exception, another exception occurred:

Traceback (most recent call last):
  File "/workspace/.pip-modules/lib/python3.8/site-packages/django/template/base.py", line 843, in _resolve_lookup
    current = current[int(bit)]
ValueError: invalid literal for int() with base 10: 'name'

During handling of the above exception, another exception occurred:

Traceback (most recent call last):
  File "/workspace/.pip-modules/lib/python3.8/site-packages/django/template/base.py", line 848, in _resolve_lookup
    raise VariableDoesNotExist("Failed lookup for key "
django.template.base.VariableDoesNotExist: Failed lookup for key [name] in <URLResolver <module 'wishes.urls' from '/workspace/worth-a-trip-drf/wishes/urls.py'> (None:None) 'api/'>
[06/Sep/2023 08:55:57] WARNING [django.request:224] Not Found: /posts/3
[06/Sep/2023 08:59:13] WARNING [django.request:224] Unauthorized: /api/dj-rest-auth/user/
